Workbook

Sheet By Instance
A1: Instance | B1: Category | C1: Subtype | D1: Material | E1: SKU | F1: Unit | G1: Quantity | H1: Unit Price | I1: Cost
A2: Estructura de Cielo | B2: 1.1. ELEMENTOS ESTRUCTURALES | C2: General | D2: MAD ASER, ESTRUC, PINO, IMPREG SECO, CALIB, 41x90,2.4 | E2: MADE0037 | F2: UN | G2: 1.2 | H2: 0 | I2: =IF(OR(G2="",H2=""),"",G2*H2)
A3: Estructura de Cielo | B3: 1.1. ELEMENTOS ESTRUCTURALES | C3: General | D3: MAD ASER, ESTRUC, PINO, IMPREG SECO, CALIB, 41x90,3.2 | E3: MADE0040 | F3: UN | G3: 1.2 | H3: 5511.81 | I3: =IF(OR(G3="",H3=""),"",G3*H3)
A4: Estructura de Cielo | B4: 1.1. ELEMENTOS ESTRUCTURALES | C4: General | D4: MAD ASER, ESTRUC, PINO, IMPREG SECO, CALIB, 41x138,3.2 | E4: MADE0029 | F4: UN | G4: 30 | H4: 0 | I4: =IF(OR(G4="",H4=""),"",G4*H4)
A5: Estructura de Cielo | B5: 1.1. ELEMENTOS ESTRUCTURALES | C5: General | D5: MAD ASER, ESTRUC, PINO, IMPREG SECO, CALIB, 41x185,3.2 | E5: MADE0033 | F5: UN | H5: 11526.87 | I5: =IF(OR(G5="",H5=""),"",G5*H5)
A6: Estructura de Cielo | B6: 1.1. ELEMENTOS ESTRUCTURALES | C6: General | D6: CLAVO R20 034X100 BK 96MM (1500UN) | E6: FIJA0031 | F6: CAJA | G6: 0.22 | H6: 24000 | I6: =IF(OR(G6="",H6=""),"",G6*H6)
A7: Estructura de Cielo | B7: 1.1. ELEMENTOS ESTRUCTURALES | C7: General | D7: PLACA ESTRUCTURALl AS 3 (76,2mm) x 6 (152mm) | E7: FIJA0279 | F7: UN | G7: 6 | H7: 360.05 | I7: =IF(OR(G7="",H7=""),"",G7*H7)
A8: Estructura de Cielo | B8: 1.1. ELEMENTOS ESTRUCTURALES | C8: General | D8: TIRAFONDO HBS 8X120 | E8: FIJA0219 | F8: UN | H8: 156.32 | I8: =IF(OR(G8="",H8=""),"",G8*H8)
D9: Subtotal Estructura de Cielo | I9: =SUM(I2:I8)
A10: Estructura de Piso | B10: 1.1. ELEMENTOS ESTRUCTURALES | C10: General | D10: MDP 18MM P5 2,05 X 3,28 MT | E10: PLAC0075 | F10: UN | G10: 7.24 | H10: 0 | I10: =IF(OR(G10="",H10=""),"",G10*H10)
A11: Estructura de Piso | B11: 1.1. ELEMENTOS ESTRUCTURALES | C11: General | D11: MDP RH 18X2440X3275 | E11: PLAC0078 | F11: UN | H11: 52577 | I11: =IF(OR(G11="",H11=""),"",G11*H11)
A12: Estructura de Piso | B12: 1.1. ELEMENTOS ESTRUCTURALES | C12: General | D12: CLAVO HELICOIDAL PROFIX 2.5X65mmX300X30 | E12: FIJA0284 | F12: CAJA | G12: 0.43 | H12: 34000 | I12: =IF(OR(G12="",H12=""),"",G12*H12)
A13: Estructura de Piso | B13: 1.1. ELEMENTOS ESTRUCTURALES | C13: General | D13: CLAVO HELICOIDAL PROFIX 2.8X75mmX250X20 | E13: FIJA0283 | F13: CAJA | G13: 0.75 | H13: 20976.5 | I13: =IF(OR(G13="",H13=""),"",G13*H13)
A14: Estructura de Piso | B14: 1.1. ELEMENTOS ESTRUCTURALES | C14: General | D14: MAD ASER, ESTRUC, PINO, IMPREG SECO, CALIB, 41x138,3.2 | E14: MADE0029 | F14: UN | G14: 9 | H14: 0 | I14: =IF(OR(G14="",H14=""),"",G14*H14)
A15: Estructura de Piso | B15: 1.1. ELEMENTOS ESTRUCTURALES | C15: General | D15: MAD ASER, ESTRUC, PINO, IMPREG SECO, CALIB, 41x185,3.2 | E15: MADE0033 | F15: UN | G15: 71 | H15: 11526.87 | I15: =IF(OR(G15="",H15=""),"",G15*H15)
A16: Estructura de Piso | B16: 1.1. ELEMENTOS ESTRUCTURALES | C16: General | D16: MAD ASER, ESTRUC, PINO, IMPREG SECO, CALIB, 41x90,2.4 | E16: MADE0037 | F16: UN | G16: 2 | H16: 0 | I16: =IF(OR(G16="",H16=""),"",G16*H16)
A17: Estructura de Piso | B17: 1.1. ELEMENTOS ESTRUCTURALES | C17: General | D17: MAD ASER, ESTRUC, PINO, IMPREG SECO, CALIB, 41x90,3.2 | E17: MADE0040 | F17: UN | G17: 0.3 | H17: 5511.81 | I17: =IF(OR(G17="",H17=""),"",G17*H17)
A18: Estructura de Piso | B18: 1.1. ELEMENTOS ESTRUCTURALES | C18: General | D18: CLAVO R20 034X100 BK 96MM (1500UN) | E18: FIJA0031 | F18: CAJA | G18: 0.43 | H18: 24000 | I18: =IF(OR(G18="",H18=""),"",G18*H18)
A19: Estructura de Piso | B19: 1.1. ELEMENTOS ESTRUCTURALES | C19: General | D19: PLACA ESTRUCTURAL AS 4 (101,6mm) x 8 (203,2mm) | E19: FIJA0280 | F19: UN | G19: 22 | H19: 664.28 | I19: =IF(OR(G19="",H19=""),"",G19*H19)
A20: Estructura de Piso | B20: 1.1. ELEMENTOS ESTRUCTURALES | C20: General | D20: ADHESIVO AEROLITE UP-4145 SACO 25 Kg | E20: ADHE0063 | F20: SACO | G20: 0.11 | H20: 114375 | I20: =IF(OR(G20="",H20=""),"",G20*H20)
A21: Estructura de Piso | B21: 1.1. ELEMENTOS ESTRUCTURALES | C21: General | D21: 2 X 6IN MEDIUM L ANGLE ZMAX ML26Z | E21: FIJA0345 | F21: UN | G21: 12 | H21: 2834 | I21: =IF(OR(G21="",H21=""),"",G21*H21)
A22: Estructura de Piso | B22: 1.1. ELEMENTOS ESTRUCTURALES | C22: General | D22: TORNILLO PARA CONECTOR SDS 1/4 X 1. 1/2 SDS25112 | E22: FIJA0429 | F22: UN | G22: 96 | H22: 180 | I22: =IF(OR(G22="",H22=""),"",G22*H22)
A23: Estructura de Piso | B23: 1.1. ELEMENTOS ESTRUCTURALES | C23: General | D23: TIRAFONDO HBS 8X120 | E23: FIJA0219 | F23: UN | H23: 156.32 | I23: =IF(OR(G23="",H23=""),"",G23*H23)
A24: Estructura de Piso | B24: 1.1. ELEMENTOS ESTRUCTURALES | C24: General | D24: TIRAFONDO TBS 6X120 | E24: FIJA0223 | F24: UN | H24: 126.73 | I24: =IF(OR(G24="",H24=""),"",G24*H24)
A25: Estructura de Piso | B25: 1.1. ELEMENTOS ESTRUCTURALES | C25: General | D25: MDP RH 12X2440X3280 | E25: PLAC0004 | F25: UN | G25: 3.2 | H25: 31884.23 | I25: =IF(OR(G25="",H25=""),"",G25*H25)
A26: Estructura de Piso | B26: 1.1. ELEMENTOS ESTRUCTURALES | C26: General | D26: GRAPA PROFIX 14/50MM X 10.000 UN - SAP GS1451 | E26: HERR0091 | F26: CAJA | G26: 0.19 | H26: 22000 | I26: =IF(OR(G26="",H26=""),"",G26*H26)
D27: Subtotal Estructura de Piso | I27: =SUM(I10:I26)
A28: Estructura de Techumbre (EPS) | B28: 1.1. ELEMENTOS ESTRUCTURALES | C28: General | D28: MAD ASER, ESTRUC, PINO, IMPREG SECO, CALIB, 41x138,3.2 | E28: MADE0029 | F28: UN | G28: 25 | H28: 0 | I28: =IF(OR(G28="",H28=""),"",G28*H28)
A29: Estructura de Techumbre (EPS) | B29: 1.1. ELEMENTOS ESTRUCTURALES | C29: General | D29: MAD ASER, ESTRUC, PINO, IMPREG SECO, CALIB, 41x90,2.4 | E29: MADE0037 | F29: UN | G29: 2 | H29: 0 | I29: =IF(OR(G29="",H29=""),"",G29*H29)
A30: Estructura de Techumbre (EPS) | B30: 1.1. ELEMENTOS ESTRUCTURALES | C30: General | D30: MAD ASER, ESTRUC, PINO, IMPREG SECO, CALIB, 41x90,3.2 | E30: MADE0040 | F30: UN | G30: 20 | H30: 5511.81 | I30: =IF(OR(G30="",H30=""),"",G30*H30)
A31: Estructura de Techumbre (EPS) | B31: 1.1. ELEMENTOS ESTRUCTURALES | C31: General | D31: CLAVO R20 034X100 BK 96MM (1500UN) | E31: FIJA0031 | F31: CAJA | G31: 0.052 | H31: 24000 | I31: =IF(OR(G31="",H31=""),"",G31*H31)
A32: Estructura de Techumbre (EPS) | B32: 1.1. ELEMENTOS ESTRUCTURALES | C32: General | D32: MDP RH 12X2440X3280 | E32: PLAC0004 | F32: UN | G32: 1.25 | H32: 31884.23 | I32: =IF(OR(G32="",H32=""),"",G32*H32)
A33: Estructura de Techumbre (EPS) | B33: 1.1. ELEMENTOS ESTRUCTURALES | C33: General | D33: OSB APA 9.5 X 1,22 X 2,44 MM | E33: PLAC0008 | F33: UN | G33: 11.5 | H33: 11696 | I33: =IF(OR(G33="",H33=""),"",G33*H33)
A34: Estructura de Techumbre (EPS) | B34: 1.1. ELEMENTOS ESTRUCTURALES | C34: General | D34: GRAPA PROFIX 14/50MM X 10.000 UN - SAP GS1451 | E34: HERR0091 | F34: CAJA | G34: 0.06 | H34: 22000 | I34: =IF(OR(G34="",H34=""),"",G34*H34)
A35: Estructura de Techumbre (EPS) | B35: 1.1. ELEMENTOS ESTRUCTURALES | C35: General | D35: PINO CEPILLADO SECO 2X2X3200 | E35: MADE0080 | F35: UN | G35: 2 | H35: 1770.4 | I35: =IF(OR(G35="",H35=""),"",G35*H35)
D36: Subtotal Estructura de Techumbre (EPS) | I36: =SUM(I28:I35)
A37: Muros Exteriores | B37: 1.1. ELEMENTOS ESTRUCTURALES | C37: General | D37: MAD ASER, ESTRUC, PINO, IMPREG SECO, CALIB, 41x138,3.2 | E37: MADE0029 | F37: UN | G37: 3 | H37: 0 | I37: =IF(OR(G37="",H37=""),"",G37*H37)
A38: Muros Exteriores | B38: 1.1. ELEMENTOS ESTRUCTURALES | C38: General | D38: MAD ASER, ESTRUC, PINO, IMPREG SECO, CALIB, 41x185,3.2 | E38: MADE0033 | F38: UN | G38: 0.7 | H38: 11526.87 | I38: =IF(OR(G38="",H38=""),"",G38*H38)
A39: Muros Exteriores | B39: 1.1. ELEMENTOS ESTRUCTURALES | C39: General | D39: MAD ASER, ESTRUC, PINO, IMPREG SECO, CALIB, 41x90,2.4 | E39: MADE0037 | F39: UN | G39: 33 | H39: 0 | I39: =IF(OR(G39="",H39=""),"",G39*H39)
A40: Muros Exteriores | B40: 1.1. ELEMENTOS ESTRUCTURALES | C40: General | D40: MAD ASER, ESTRUC, PINO, IMPREG SECO, CALIB, 41x90,3.2 | E40: MADE0040 | F40: UN | G40: 165 | H40: 5511.81 | I40: =IF(OR(G40="",H40=""),"",G40*H40)
...

Sheet Total Materials
A1: SKU | B1: Material | C1: Subtype | D1: Unit | E1: Quantity | F1: Unit Price | G1: Cost
A2: ACER0002 | B2: ALAMBRE GALVANIZADO # 18 | C2: General | D2: KG | E2: =IF(SUMIFS('By Instance'!$G:$G,'By Instance'!$E:$E,A2,'By Instance'!$C:$C,C2)=0,"",SUMIFS('By Instance'!$G:$G,'By Instance'!$E:$E,A2,'By Instance'!$C:$C,C2)) | F2: =IF(OR(E2="",E2=0,G2=""),"",G2/E2) | G2: =IF(SUMIFS('By Instance'!$I:$I,'By Instance'!$E:$E,A2,'By Instance'!$C:$C,C2)=0,"",SUMIFS('By Instance'!$I:$I,'By Instance'!$E:$E,A2,'By Instance'!$C:$C,C2))
A3: ACER0044 | B3: PERFIL RECTANGULAR 200 X 100 X 5 X 6000MM | C3: General | D3: UN | E3: =IF(SUMIFS('By Instance'!$G:$G,'By Instance'!$E:$E,A3,'By Instance'!$C:$C,C3)=0,"",SUMIFS('By Instance'!$G:$G,'By Instance'!$E:$E,A3,'By Instance'!$C:$C,C3)) | F3: =IF(OR(E3="",E3=0,G3=""),"",G3/E3) | G3: =IF(SUMIFS('By Instance'!$I:$I,'By Instance'!$E:$E,A3,'By Instance'!$C:$C,C3)=0,"",SUMIFS('By Instance'!$I:$I,'By Instance'!$E:$E,A3,'By Instance'!$C:$C,C3))
A4: ACER0094 | B4: TUBO REDONDO 1 3/4 PULGX2MMX6MT | C4: General | D4: UN | E4: =IF(SUMIFS('By Instance'!$G:$G,'By Instance'!$E:$E,A4,'By Instance'!$C:$C,C4)=0,"",SUMIFS('By Instance'!$G:$G,'By Instance'!$E:$E,A4,'By Instance'!$C:$C,C4)) | F4: =IF(OR(E4="",E4=0,G4=""),"",G4/E4) | G4: =IF(SUMIFS('By Instance'!$I:$I,'By Instance'!$E:$E,A4,'By Instance'!$C:$C,C4)=0,"",SUMIFS('By Instance'!$I:$I,'By Instance'!$E:$E,A4,'By Instance'!$C:$C,C4))
A5: ADHE0012 | B5: ADHESIVO VINILIT TRADICIONAL 240CC | C5: General | D5: UN | E5: =IF(SUMIFS('By Instance'!$G:$G,'By Instance'!$E:$E,A5,'By Instance'!$C:$C,C5)=0,"",SUMIFS('By Instance'!$G:$G,'By Instance'!$E:$E,A5,'By Instance'!$C:$C,C5)) | F5: =IF(OR(E5="",E5=0,G5=""),"",G5/E5) | G5: =IF(SUMIFS('By Instance'!$I:$I,'By Instance'!$E:$E,A5,'By Instance'!$C:$C,C5)=0,"",SUMIFS('By Instance'!$I:$I,'By Instance'!$E:$E,A5,'By Instance'!$C:$C,C5))
A6: ADHE0021 | B6: CINTA ENMASCARAR 1 (PEGOTE) | C6: General | D6: UN | E6: =IF(SUMIFS('By Instance'!$G:$G,'By Instance'!$E:$E,A6,'By Instance'!$C:$C,C6)=0,"",SUMIFS('By Instance'!$G:$G,'By Instance'!$E:$E,A6,'By Instance'!$C:$C,C6)) | F6: =IF(OR(E6="",E6=0,G6=""),"",G6/E6) | G6: =IF(SUMIFS('By Instance'!$I:$I,'By Instance'!$E:$E,A6,'By Instance'!$C:$C,C6)=0,"",SUMIFS('By Instance'!$I:$I,'By Instance'!$E:$E,A6,'By Instance'!$C:$C,C6))
A7: ADHE0022 | B7: CINTA ENMASCARAR 2 (PEGOTE) | C7: General | D7: UN | E7: =IF(SUMIFS('By Instance'!$G:$G,'By Instance'!$E:$E,A7,'By Instance'!$C:$C,C7)=0,"",SUMIFS('By Instance'!$G:$G,'By Instance'!$E:$E,A7,'By Instance'!$C:$C,C7)) | F7: =IF(OR(E7="",E7=0,G7=""),"",G7/E7) | G7: =IF(SUMIFS('By Instance'!$I:$I,'By Instance'!$E:$E,A7,'By Instance'!$C:$C,C7)=0,"",SUMIFS('By Instance'!$I:$I,'By Instance'!$E:$E,A7,'By Instance'!$C:$C,C7))
A8: ADHE0061 | B8: ADHESIVO DE CONTACTO AGOREX 60 | C8: General | D8: UN | E8: =IF(SUMIFS('By Instance'!$G:$G,'By Instance'!$E:$E,A8,'By Instance'!$C:$C,C8)=0,"",SUMIFS('By Instance'!$G:$G,'By Instance'!$E:$E,A8,'By Instance'!$C:$C,C8)) | F8: =IF(OR(E8="",E8=0,G8=""),"",G8/E8) | G8: =IF(SUMIFS('By Instance'!$I:$I,'By Instance'!$E:$E,A8,'By Instance'!$C:$C,C8)=0,"",SUMIFS('By Instance'!$I:$I,'By Instance'!$E:$E,A8,'By Instance'!$C:$C,C8))
A9: ADHE0063 | B9: ADHESIVO AEROLITE UP-4145 SACO 25 Kg | C9: General | D9: SACO | E9: =IF(SUMIFS('By Instance'!$G:$G,'By Instance'!$E:$E,A9,'By Instance'!$C:$C,C9)=0,"",SUMIFS('By Instance'!$G:$G,'By Instance'!$E:$E,A9,'By Instance'!$C:$C,C9)) | F9: =IF(OR(E9="",E9=0,G9=""),"",G9/E9) | G9: =IF(SUMIFS('By Instance'!$I:$I,'By Instance'!$E:$E,A9,'By Instance'!$C:$C,C9)=0,"",SUMIFS('By Instance'!$I:$I,'By Instance'!$E:$E,A9,'By Instance'!$C:$C,C9))
A10: ADHE0069 | B10: COLA FRIA 20KG | C10: General | D10: TINETA | E10: =IF(SUMIFS('By Instance'!$G:$G,'By Instance'!$E:$E,A10,'By Instance'!$C:$C,C10)=0,"",SUMIFS('By Instance'!$G:$G,'By Instance'!$E:$E,A10,'By Instance'!$C:$C,C10)) | F10: =IF(OR(E10="",E10=0,G10=""),"",G10/E10) | G10: =IF(SUMIFS('By Instance'!$I:$I,'By Instance'!$E:$E,A10,'By Instance'!$C:$C,C10)=0,"",SUMIFS('By Instance'!$I:$I,'By Instance'!$E:$E,A10,'By Instance'!$C:$C,C10))
A11: AGLL0002 | B11: CLIP ABRAZADERA TUBO BAJADA 80 [MM] BLANCO | C11: General | D11: UN | E11: =IF(SUMIFS('By Instance'!$G:$G,'By Instance'!$E:$E,A11,'By Instance'!$C:$C,C11)=0,"",SUMIFS('By Instance'!$G:$G,'By Instance'!$E:$E,A11,'By Instance'!$C:$C,C11)) | F11: =IF(OR(E11="",E11=0,G11=""),"",G11/E11) | G11: =IF(SUMIFS('By Instance'!$I:$I,'By Instance'!$E:$E,A11,'By Instance'!$C:$C,C11)=0,"",SUMIFS('By Instance'!$I:$I,'By Instance'!$E:$E,A11,'By Instance'!$C:$C,C11))
A12: AGLL0004 | B12: CANALETA AGUA LLUVIA PRO 110 [MM] x 4 [M] BLANCA 2028229 | C12: General | D12: UN | E12: =IF(SUMIFS('By Instance'!$G:$G,'By Instance'!$E:$E,A12,'By Instance'!$C:$C,C12)=0,"",SUMIFS('By Instance'!$G:$G,'By Instance'!$E:$E,A12,'By Instance'!$C:$C,C12)) | F12: =IF(OR(E12="",E12=0,G12=""),"",G12/E12) | G12: =IF(SUMIFS('By Instance'!$I:$I,'By Instance'!$E:$E,A12,'By Instance'!$C:$C,C12)=0,"",SUMIFS('By Instance'!$I:$I,'By Instance'!$E:$E,A12,'By Instance'!$C:$C,C12))
A13: AGLL0008 | B13: COPLA TUBO BAJADA 80 [MM] BLANCO 2028872 | C13: General | D13: UN | E13: =IF(SUMIFS('By Instance'!$G:$G,'By Instance'!$E:$E,A13,'By Instance'!$C:$C,C13)=0,"",SUMIFS('By Instance'!$G:$G,'By Instance'!$E:$E,A13,'By Instance'!$C:$C,C13)) | F13: =IF(OR(E13="",E13=0,G13=""),"",G13/E13) | G13: =IF(SUMIFS('By Instance'!$I:$I,'By Instance'!$E:$E,A13,'By Instance'!$C:$C,C13)=0,"",SUMIFS('By Instance'!$I:$I,'By Instance'!$E:$E,A13,'By Instance'!$C:$C,C13))
... A177: FIJA0411 | B177: TOR VOLC/MAD CRS FOSFATADO 6 X 1.1/4 | C177: General | D177: UN | E177: =IF(SUMIFS('By Instance'!$G:$G,'By Instance'!$E:$E,A177,'By Instance'!$C:$C,C177)=0,"",SUMIFS('By Instance'!$G:$G,'By Instance'!$E:$E,A177,'By Instance'!$C:$C,C177)) | F177: =IF(OR(E177="",E177=0,G177=""),"",G177/E177) | G177: =IF(SUMIFS('By Instance'!$I:$I,'By Instance'!$E:$E,A177,'By Instance'!$C:$C,C177)=0,"",SUMIFS('By Instance'!$I:$I,'By Instance'!$E:$E,A177,'By Instance'!$C:$C,C177))
A178: FIJA0416 | B178: TORNILLO C/HEX APERF ESPAD/LABIO EPDM 10-12X2.1/2 | C178: General | E178: =IF(SUMIFS('By Instance'!$G:$G,'By Instance'!$E:$E,A178,'By Instance'!$C:$C,C178)=0,"",SUMIFS('By Instance'!$G:$G,'By Instance'!$E:$E,A178,'By Instance'!$C:$C,C178)) | F178: =IF(OR(E178="",E178=0,G178=""),"",G178/E178) | G178: =IF(SUMIFS('By Instance'!$I:$I,'By Instance'!$E:$E,A178,'By Instance'!$C:$C,C178)=0,"",SUMIFS('By Instance'!$I:$I,'By Instance'!$E:$E,A178,'By Instance'!$C:$C,C178))
A179: FIJA0424 | B179: AUTOPERFORANTE STITCH HEX- 1/4 - 14/7/8 | C179: General | D179: UN | E179: =IF(SUMIFS('By Instance'!$G:$G,'By Instance'!$E:$E,A179,'By Instance'!$C:$C,C179)=0,"",SUMIFS('By Instance'!$G:$G,'By Instance'!$E:$E,A179,'By Instance'!$C:$C,C179)) | F179: =IF(OR(E179="",E179=0,G179=""),"",G179/E179) | G179: =IF(SUMIFS('By Instance'!$I:$I,'By Instance'!$E:$E,A179,'By Instance'!$C:$C,C179)=0,"",SUMIFS('By Instance'!$I:$I,'By Instance'!$E:$E,A179,'By Instance'!$C:$C,C179))
A180: FIJA0429 | B180: TORNILLO PARA CONECTOR SDS 1/4 X 1. 1/2 SDS25112 | C180: General | D180: UN | E180: =IF(SUMIFS('By Instance'!$G:$G,'By Instance'!$E:$E,A180,'By Instance'!$C:$C,C180)=0,"",SUMIFS('By Instance'!$G:$G,'By Instance'!$E:$E,A180,'By Instance'!$C:$C,C180)) | F180: =IF(OR(E180="",E180=0,G180=""),"",G180/E180) | G180: =IF(SUMIFS('By Instance'!$I:$I,'By Instance'!$E:$E,A180,'By Instance'!$C:$C,C180)=0,"",SUMIFS('By Instance'!$I:$I,'By Instance'!$E:$E,A180,'By Instance'!$C:$C,C180))
A181: FIJA0487 | B181: TIRAFONDO HBS 5X80 | C181: General | D181: UN | E181: =IF(SUMIFS('By Instance'!$G:$G,'By Instance'!$E:$E,A181,'By Instance'!$C:$C,C181)=0,"",SUMIFS('By Instance'!$G:$G,'By Instance'!$E:$E,A181,'By Instance'!$C:$C,C181)) | F181: =IF(OR(E181="",E181=0,G181=""),"",G181/E181) | G181: =IF(SUMIFS('By Instance'!$I:$I,'By Instance'!$E:$E,A181,'By Instance'!$C:$C,C181)=0,"",SUMIFS('By Instance'!$I:$I,'By Instance'!$E:$E,A181,'By Instance'!$C:$C,C181))
A182: FIJA0498 | B182: TIRAFONDO TBS 8X250 | C182: General | D182: UN | E182: =IF(SUMIFS('By Instance'!$G:$G,'By Instance'!$E:$E,A182,'By Instance'!$C:$C,C182)=0,"",SUMIFS('By Instance'!$G:$G,'By Instance'!$E:$E,A182,'By Instance'!$C:$C,C182)) | F182: =IF(OR(E182="",E182=0,G182=""),"",G182/E182) | G182: =IF(SUMIFS('By Instance'!$I:$I,'By Instance'!$E:$E,A182,'By Instance'!$C:$C,C182)=0,"",SUMIFS('By Instance'!$I:$I,'By Instance'!$E:$E,A182,'By Instance'!$C:$C,C182))
A183: FIJA0499 | B183: TORNILLO ESTRUCTURAL DOBLE ROSCA Ø 8.0 X 275MM PROTEC + T40 | C183: General | D183: UN | E183: =IF(SUMIFS('By Instance'!$G:$G,'By Instance'!$E:$E,A183,'By Instance'!$C:$C,C183)=0,"",SUMIFS('By Instance'!$G:$G,'By Instance'!$E:$E,A183,'By Instance'!$C:$C,C183)) | F183: =IF(OR(E183="",E183=0,G183=""),"",G183/E183) | G183: =IF(SUMIFS('By Instance'!$I:$I,'By Instance'!$E:$E,A183,'By Instance'!$C:$C,C183)=0,"",SUMIFS('By Instance'!$I:$I,'By Instance'!$E:$E,A183,'By Instance'!$C:$C,C183))
A184: FIJA0502 | B184: CLAVO ANILL. PROFIX GALV 2.9X60MMX600X8R | C184: General | D184: CAJA | E184: =IF(SUMIFS('By Instance'!$G:$G,'By Instance'!$E:$E,A184,'By Instance'!$C:$C,C184)=0,"",SUMIFS('By Instance'!$G:$G,'By Instance'!$E:$E,A184,'By Instance'!$C:$C,C184)) | F184: =IF(OR(E184="",E184=0,G184=""),"",G184/E184) | G184: =IF(SUMIFS('By Instance'!$I:$I,'By Instance'!$E:$E,A184,'By Instance'!$C:$C,C184)=0,"",SUMIFS('By Instance'!$I:$I,'By Instance'!$E:$E,A184,'By Instance'!$C:$C,C184))
A185: HERR0008 | B185: AMARRA PLASTICA BLANCA 4,8X287MM | C185: General | D185: UN | E185: =IF(SUMIFS('By Instance'!$G:$G,'By Instance'!$E:$E,A185,'By Instance'!$C:$C,C185)=0,"",SUMIFS('By Instance'!$G:$G,'By Instance'!$E:$E,A185,'By Instance'!$C:$C,C185)) | F185: =IF(OR(E185="",E185=0,G185=""),"",G185/E185) | G185: =IF(SUMIFS('By Instance'!$I:$I,'By Instance'!$E:$E,A185,'By Instance'!$C:$C,C185)=0,"",SUMIFS('By Instance'!$I:$I,'By Instance'!$E:$E,A185,'By Instance'!$C:$C,C185))
A186: HERR0033 | B186: BROCHA 1 | C186: General | D186: UN | E186: =IF(SUMIFS('By Instance'!$G:$G,'By Instance'!$E:$E,A186,'By Instance'!$C:$C,C186)=0,"",SUMIFS('By Instance'!$G:$G,'By Instance'!$E:$E,A186,'By Instance'!$C:$C,C186)) | F186: =IF(OR(E186="",E186=0,G186=""),"",G186/E186) | G186: =IF(SUMIFS('By Instance'!$I:$I,'By Instance'!$E:$E,A186,'By Instance'!$C:$C,C186)=0,"",SUMIFS('By Instance'!$I:$I,'By Instance'!$E:$E,A186,'By Instance'!$C:$C,C186))
A187: HERR0034 | B187: BROCHA 1-1/2 | C187: General | D187: UN | E187: =IF(SUMIFS('By Instance'!$G:$G,'By Instance'!$E:$E,A187,'By Instance'!$C:$C,C187)=0,"",SUMIFS('By Instance'!$G:$G,'By Instance'!$E:$E,A187,'By Instance'!$C:$C,C187)) | F187: =IF(OR(E187="",E187=0,G187=""),"",G187/E187) | G187: =IF(SUMIFS('By Instance'!$I:$I,'By Instance'!$E:$E,A187,'By Instance'!$C:$C,C187)=0,"",SUMIFS('By Instance'!$I:$I,'By Instance'!$E:$E,A187,'By Instance'!$C:$C,C187))
A188: HERR0035 | B188: BROCHA 2-1/2 | C188: General | D188: UN | E188: =IF(SUMIFS('By Instance'!$G:$G,'By Instance'!$E:$E,A188,'By Instance'!$C:$C,C188)=0,"",SUMIFS('By Instance'!$G:$G,'By Instance'!$E:$E,A188,'By Instance'!$C:$C,C188)) | F188: =IF(OR(E188="",E188=0,G188=""),"",G188/E188) | G188: =IF(SUMIFS('By Instance'!$I:$I,'By Instance'!$E:$E,A188,'By Instance'!$C:$C,C188)=0,"",SUMIFS('By Instance'!$I:$I,'By Instance'!$E:$E,A188,'By Instance'!$C:$C,C188))
A189: HERR0036 | B189: BROCHA 3 | C189: General | D189: UN | E189: =IF(SUMIFS('By Instance'!$G:$G,'By Instance'!$E:$E,A189,'By Instance'!$C:$C,C189)=0,"",SUMIFS('By Instance'!$G:$G,'By Instance'!$E:$E,A189,'By Instance'!$C:$C,C189)) | F189: =IF(OR(E189="",E189=0,G189=""),"",G189/E189) | G189: =IF(SUMIFS('By Instance'!$I:$I,'By Instance'!$E:$E,A189,'By Instance'!$C:$C,C189)=0,"",SUMIFS('By Instance'!$I:$I,'By Instance'!$E:$E,A189,'By Instance'!$C:$C,C189))
A190: HERR0052 | B190: CINTA GALVANIZADA PERFORADA 10MTS | C190: General | D190: UN | E190: =IF(SUMIFS('By Instance'!$G:$G,'By Instance'!$E:$E,A190,'By Instance'!$C:$C,C190)=0,"",SUMIFS('By Instance'!$G:$G,'By Instance'!$E:$E,A190,'By Instance'!$C:$C,C190)) | F190: =IF(OR(E190="",E190=0,G190=""),"",G190/E190) | G190: =IF(SUMIFS('By Instance'!$I:$I,'By Instance'!$E:$E,A190,'By Instance'!$C:$C,C190)=0,"",SUMIFS('By Instance'!$I:$I,'By Instance'!$E:$E,A190,'By Instance'!$C:$C,C190))
... A223: LEGACY-1071 | B223: TIRAFONDO TBS 6X240 | C223: General | D223: UN | E223: =IF(SUMIFS('By Instance'!$G:$G,'By Instance'!$E:$E,A223,'By Instance'!$C:$C,C223)=0,"",SUMIFS('By Instance'!$G:$G,'By Instance'!$E:$E,A223,'By Instance'!$C:$C,C223)) | F223: =IF(OR(E223="",E223=0,G223=""),"",G223/E223) | G223: =IF(SUMIFS('By Instance'!$I:$I,'By Instance'!$E:$E,A223,'By Instance'!$C:$C,C223)=0,"",SUMIFS('By Instance'!$I:$I,'By Instance'!$E:$E,A223,'By Instance'!$C:$C,C223))
A224: LEGACY-MATERIAL-1088 | B224: Legacy missing material 1088 | C224: General | E224: =IF(SUMIFS('By Instance'!$G:$G,'By Instance'!$E:$E,A224,'By Instance'!$C:$C,C224)=0,"",SUMIFS('By Instance'!$G:$G,'By Instance'!$E:$E,A224,'By Instance'!$C:$C,C224)) | F224: =IF(OR(E224="",E224=0,G224=""),"",G224/E224) | G224: =IF(SUMIFS('By Instance'!$I:$I,'By Instance'!$E:$E,A224,'By Instance'!$C:$C,C224)=0,"",SUMIFS('By Instance'!$I:$I,'By Instance'!$E:$E,A224,'By Instance'!$C:$C,C224))
A225: LUBR0002 | B225: LUBRICANTE PVC 500GRS | C225: General | D225: UN | E225: =IF(SUMIFS('By Instance'!$G:$G,'By Instance'!$E:$E,A225,'By Instance'!$C:$C,C225)=0,"",SUMIFS('By Instance'!$G:$G,'By Instance'!$E:$E,A225,'By Instance'!$C:$C,C225)) | F225: =IF(OR(E225="",E225=0,G225=""),"",G225/E225) | G225: =IF(SUMIFS('By Instance'!$I:$I,'By Instance'!$E:$E,A225,'By Instance'!$C:$C,C225)=0,"",SUMIFS('By Instance'!$I:$I,'By Instance'!$E:$E,A225,'By Instance'!$C:$C,C225))
A226: MADE0008 | B226: PINO 2 X 10 X 3.20 MT CEPILLADO SECO | C226: General | D226: UN | E226: =IF(SUMIFS('By Instance'!$G:$G,'By Instance'!$E:$E,A226,'By Instance'!$C:$C,C226)=0,"",SUMIFS('By Instance'!$G:$G,'By Instance'!$E:$E,A226,'By Instance'!$C:$C,C226)) | F226: =IF(OR(E226="",E226=0,G226=""),"",G226/E226) | G226: =IF(SUMIFS('By Instance'!$I:$I,'By Instance'!$E:$E,A226,'By Instance'!$C:$C,C226)=0,"",SUMIFS('By Instance'!$I:$I,'By Instance'!$E:$E,A226,'By Instance'!$C:$C,C226))
A227: MADE0029 | B227: MAD ASER, ESTRUC, PINO, IMPREG SECO, CALIB, 41x138,3.2 | C227: General | D227: UN | E227: =IF(SUMIFS('By Instance'!$G:$G,'By Instance'!$E:$E,A227,'By Instance'!$C:$C,C227)=0,"",SUMIFS('By Instance'!$G:$G,'By Instance'!$E:$E,A227,'By Instance'!$C:$C,C227)) | F227: =IF(OR(E227="",E227=0,G227=""),"",G227/E227) | G227: =IF(SUMIFS('By Instance'!$I:$I,'By Instance'!$E:$E,A227,'By Instance'!$C:$C,C227)=0,"",SUMIFS('By Instance'!$I:$I,'By Instance'!$E:$E,A227,'By Instance'!$C:$C,C227))
A228: MADE0033 | B228: MAD ASER, ESTRUC, PINO, IMPREG SECO, CALIB, 41x185,3.2 | C228: General | D228: UN | E228: =IF(SUMIFS('By Instance'!$G:$G,'By Instance'!$E:$E,A228,'By Instance'!$C:$C,C228)=0,"",SUMIFS('By Instance'!$G:$G,'By Instance'!$E:$E,A228,'By Instance'!$C:$C,C228)) | F228: =IF(OR(E228="",E228=0,G228=""),"",G228/E228) | G228: =IF(SUMIFS('By Instance'!$I:$I,'By Instance'!$E:$E,A228,'By Instance'!$C:$C,C228)=0,"",SUMIFS('By Instance'!$I:$I,'By Instance'!$E:$E,A228,'By Instance'!$C:$C,C228))
A229: MADE0037 | B229: MAD ASER, ESTRUC, PINO, IMPREG SECO, CALIB, 41x90,2.4 | C229: General | D229: UN | E229: =IF(SUMIFS('By Instance'!$G:$G,'By Instance'!$E:$E,A229,'By Instance'!$C:$C,C229)=0,"",SUMIFS('By Instance'!$G:$G,'By Instance'!$E:$E,A229,'By Instance'!$C:$C,C229)) | F229: =IF(OR(E229="",E229=0,G229=""),"",G229/E229) | G229: =IF(SUMIFS('By Instance'!$I:$I,'By Instance'!$E:$E,A229,'By Instance'!$C:$C,C229)=0,"",SUMIFS('By Instance'!$I:$I,'By Instance'!$E:$E,A229,'By Instance'!$C:$C,C229))
A230: MADE0040 | B230: MAD ASER, ESTRUC, PINO, IMPREG SECO, CALIB, 41x90,3.2 | C230: General | D230: UN | E230: =IF(SUMIFS('By Instance'!$G:$G,'By Instance'!$E:$E,A230,'By Instance'!$C:$C,C230)=0,"",SUMIFS('By Instance'!$G:$G,'By Instance'!$E:$E,A230,'By Instance'!$C:$C,C230)) | F230: =IF(OR(E230="",E230=0,G230=""),"",G230/E230) | G230: =IF(SUMIFS('By Instance'!$I:$I,'By Instance'!$E:$E,A230,'By Instance'!$C:$C,C230)=0,"",SUMIFS('By Instance'!$I:$I,'By Instance'!$E:$E,A230,'By Instance'!$C:$C,C230))
A231: MADE0080 | B231: PINO CEPILLADO SECO 2X2X3200 | C231: General | D231: UN | E231: =IF(SUMIFS('By Instance'!$G:$G,'By Instance'!$E:$E,A231,'By Instance'!$C:$C,C231)=0,"",SUMIFS('By Instance'!$G:$G,'By Instance'!$E:$E,A231,'By Instance'!$C:$C,C231)) | F231: =IF(OR(E231="",E231=0,G231=""),"",G231/E231) | G231: =IF(SUMIFS('By Instance'!$I:$I,'By Instance'!$E:$E,A231,'By Instance'!$C:$C,C231)=0,"",SUMIFS('By Instance'!$I:$I,'By Instance'!$E:$E,A231,'By Instance'!$C:$C,C231))
A232: MAESTRANZA0001 | B232: PLACA L - 200+75 X 400 X 5MM | C232: General | D232: KG | E232: =IF(SUMIFS('By Instance'!$G:$G,'By Instance'!$E:$E,A232,'By Instance'!$C:$C,C232)=0,"",SUMIFS('By Instance'!$G:$G,'By Instance'!$E:$E,A232,'By Instance'!$C:$C,C232)) | F232: =IF(OR(E232="",E232=0,G232=""),"",G232/E232) | G232: =IF(SUMIFS('By Instance'!$I:$I,'By Instance'!$E:$E,A232,'By Instance'!$C:$C,C232)=0,"",SUMIFS('By Instance'!$I:$I,'By Instance'!$E:$E,A232,'By Instance'!$C:$C,C232))
A233: MEMB0011 | B233: MEMBRANA HIDROFUGA 80G/M2 75M2 IMP | C233: General | D233: ROLLO | E233: =IF(SUMIFS('By Instance'!$G:$G,'By Instance'!$E:$E,A233,'By Instance'!$C:$C,C233)=0,"",SUMIFS('By Instance'!$G:$G,'By Instance'!$E:$E,A233,'By Instance'!$C:$C,C233)) | F233: =IF(OR(E233="",E233=0,G233=""),"",G233/E233) | G233: =IF(SUMIFS('By Instance'!$I:$I,'By Instance'!$E:$E,A233,'By Instance'!$C:$C,C233)=0,"",SUMIFS('By Instance'!$I:$I,'By Instance'!$E:$E,A233,'By Instance'!$C:$C,C233))
A234: MODU0033 | B234: GUARDAPOLVO CHAFLAN 45MM LARGO 2,4 | C234: General | D234: UN | E234: =IF(SUMIFS('By Instance'!$G:$G,'By Instance'!$E:$E,A234,'By Instance'!$C:$C,C234)=0,"",SUMIFS('By Instance'!$G:$G,'By Instance'!$E:$E,A234,'By Instance'!$C:$C,C234)) | F234: =IF(OR(E234="",E234=0,G234=""),"",G234/E234) | G234: =IF(SUMIFS('By Instance'!$I:$I,'By Instance'!$E:$E,A234,'By Instance'!$C:$C,C234)=0,"",SUMIFS('By Instance'!$I:$I,'By Instance'!$E:$E,A234,'By Instance'!$C:$C,C234))
A235: MODU0043 | B235: CUBREJUNTA TRANSICION MANDALA GRECO PVC | C235: General | D235: UN | E235: =IF(SUMIFS('By Instance'!$G:$G,'By Instance'!$E:$E,A235,'By Instance'!$C:$C,C235)=0,"",SUMIFS('By Instance'!$G:$G,'By Instance'!$E:$E,A235,'By Instance'!$C:$C,C235)) | F235: =IF(OR(E235="",E235=0,G235=""),"",G235/E235) | G235: =IF(SUMIFS('By Instance'!$I:$I,'By Instance'!$E:$E,A235,'By Instance'!$C:$C,C235)=0,"",SUMIFS('By Instance'!$I:$I,'By Instance'!$E:$E,A235,'By Instance'!$C:$C,C235))
...
